[2025-10-03T14:40:10.821+0000] {local_task_job_runner.py:120} INFO - ::group::Pre task execution logs
[2025-10-03T14:40:10.881+0000] {taskinstance.py:2076} INFO - Dependencies all met for dep_context=non-requeueable deps ti=<TaskInstance: dbt_dag.dbt_deps manual__2025-10-03T14:34:47.803626+00:00 [queued]>
[2025-10-03T14:40:10.893+0000] {taskinstance.py:2076} INFO - Dependencies all met for dep_context=requeueable deps ti=<TaskInstance: dbt_dag.dbt_deps manual__2025-10-03T14:34:47.803626+00:00 [queued]>
[2025-10-03T14:40:10.894+0000] {taskinstance.py:2306} INFO - Starting attempt 2 of 2
[2025-10-03T14:40:10.925+0000] {taskinstance.py:2330} INFO - Executing <Task(BashOperator): dbt_deps> on 2025-10-03 14:34:47.803626+00:00
[2025-10-03T14:40:10.949+0000] {warnings.py:112} WARNING - /home/***/.local/lib/python3.12/site-packages/***/task/task_runner/standard_task_runner.py:62: DeprecationWarning: This process (pid=1290) is multi-threaded, use of fork() may lead to deadlocks in the child.
  pid = os.fork()

[2025-10-03T14:40:10.953+0000] {standard_task_runner.py:64} INFO - Started process 1299 to run task
[2025-10-03T14:40:10.953+0000] {standard_task_runner.py:90} INFO - Running: ['***', 'tasks', 'run', 'dbt_dag', 'dbt_deps', 'manual__2025-10-03T14:34:47.803626+00:00', '--job-id', '27', '--raw', '--subdir', 'DAGS_FOLDER/dbt_dag.py', '--cfg-path', '/tmp/tmp2jcsa4c1']
[2025-10-03T14:40:10.958+0000] {standard_task_runner.py:91} INFO - Job 27: Subtask dbt_deps
[2025-10-03T14:40:11.059+0000] {task_command.py:426} INFO - Running <TaskInstance: dbt_dag.dbt_deps manual__2025-10-03T14:34:47.803626+00:00 [running]> on host 68ec1039cc61
[2025-10-03T14:40:11.215+0000] {taskinstance.py:2648} INFO - Exporting env vars: AIRFLOW_CTX_DAG_OWNER='***' AIRFLOW_CTX_DAG_ID='dbt_dag' AIRFLOW_CTX_TASK_ID='dbt_deps' AIRFLOW_CTX_EXECUTION_DATE='2025-10-03T14:34:47.803626+00:00' AIRFLOW_CTX_TRY_NUMBER='2' AIRFLOW_CTX_DAG_RUN_ID='manual__2025-10-03T14:34:47.803626+00:00'
[2025-10-03T14:40:11.219+0000] {taskinstance.py:430} INFO - ::endgroup::
[2025-10-03T14:40:11.221+0000] {subprocess.py:63} INFO - Tmp dir root location: /tmp
[2025-10-03T14:40:11.229+0000] {subprocess.py:75} INFO - Running command: ['/usr/bin/bash', '-c', 'cd /opt/***/dbt && dbt deps']
[2025-10-03T14:40:11.266+0000] {subprocess.py:86} INFO - Output:
[2025-10-03T14:40:11.322+0000] {subprocess.py:93} INFO - /usr/bin/bash: line 1: cd: /opt/***/dbt: No such file or directory
[2025-10-03T14:40:11.324+0000] {subprocess.py:97} INFO - Command exited with return code 1
[2025-10-03T14:40:11.327+0000] {taskinstance.py:441} INFO - ::group::Post task execution logs
[2025-10-03T14:40:11.369+0000] {taskinstance.py:2905} ERROR - Task failed with exception
Traceback (most recent call last):
  File "/home/airflow/.local/lib/python3.12/site-packages/airflow/models/taskinstance.py", line 465, in _execute_task
    result = _execute_callable(context=context, **execute_callable_kwargs)
             ^^^^^^^^^^^^^^^^^^^^^^^^^^^^^^^^^^^^^^^^^^^^^^^^^^^^^^^^^^^^^
  File "/home/airflow/.local/lib/python3.12/site-packages/airflow/models/taskinstance.py", line 432, in _execute_callable
    return execute_callable(context=context, **execute_callable_kwargs)
           ^^^^^^^^^^^^^^^^^^^^^^^^^^^^^^^^^^^^^^^^^^^^^^^^^^^^^^^^^^^^
  File "/home/airflow/.local/lib/python3.12/site-packages/airflow/models/baseoperator.py", line 401, in wrapper
    return func(self, *args, **kwargs)
           ^^^^^^^^^^^^^^^^^^^^^^^^^^^
  File "/home/airflow/.local/lib/python3.12/site-packages/airflow/operators/bash.py", line 243, in execute
    raise AirflowException(
airflow.exceptions.AirflowException: Bash command failed. The command returned a non-zero exit code 1.
[2025-10-03T14:40:11.416+0000] {taskinstance.py:1206} INFO - Marking task as FAILED. dag_id=dbt_dag, task_id=dbt_deps, run_id=manual__2025-10-03T14:34:47.803626+00:00, execution_date=20251003T143447, start_date=20251003T144010, end_date=20251003T144011
[2025-10-03T14:40:11.501+0000] {standard_task_runner.py:110} ERROR - Failed to execute job 27 for task dbt_deps (Bash command failed. The command returned a non-zero exit code 1.; 1299)
[2025-10-03T14:40:11.572+0000] {local_task_job_runner.py:243} INFO - Task exited with return code 1
[2025-10-03T14:40:11.645+0000] {taskinstance.py:3503} INFO - 0 downstream tasks scheduled from follow-on schedule check
[2025-10-03T14:40:11.663+0000] {local_task_job_runner.py:222} INFO - ::endgroup::
