[2025-10-03T15:25:18.201+0000] {local_task_job_runner.py:120} INFO - ::group::Pre task execution logs
[2025-10-03T15:25:18.250+0000] {taskinstance.py:2076} INFO - Dependencies all met for dep_context=non-requeueable deps ti=<TaskInstance: dbt_dag.dbt_deps manual__2025-10-03T15:25:03.732385+00:00 [queued]>
[2025-10-03T15:25:18.265+0000] {taskinstance.py:2076} INFO - Dependencies all met for dep_context=requeueable deps ti=<TaskInstance: dbt_dag.dbt_deps manual__2025-10-03T15:25:03.732385+00:00 [queued]>
[2025-10-03T15:25:18.266+0000] {taskinstance.py:2306} INFO - Starting attempt 1 of 2
[2025-10-03T15:25:18.294+0000] {taskinstance.py:2330} INFO - Executing <Task(BashOperator): dbt_deps> on 2025-10-03 15:25:03.732385+00:00
[2025-10-03T15:25:18.309+0000] {warnings.py:112} WARNING - /home/***/.local/lib/python3.12/site-packages/***/task/task_runner/standard_task_runner.py:62: DeprecationWarning: This process (pid=99) is multi-threaded, use of fork() may lead to deadlocks in the child.
  pid = os.fork()

[2025-10-03T15:25:18.312+0000] {standard_task_runner.py:64} INFO - Started process 108 to run task
[2025-10-03T15:25:18.313+0000] {standard_task_runner.py:90} INFO - Running: ['***', 'tasks', 'run', 'dbt_dag', 'dbt_deps', 'manual__2025-10-03T15:25:03.732385+00:00', '--job-id', '47', '--raw', '--subdir', 'DAGS_FOLDER/test_ml_dag.py', '--cfg-path', '/tmp/tmp0hr7_qc0']
[2025-10-03T15:25:18.319+0000] {standard_task_runner.py:91} INFO - Job 47: Subtask dbt_deps
[2025-10-03T15:25:18.415+0000] {task_command.py:426} INFO - Running <TaskInstance: dbt_dag.dbt_deps manual__2025-10-03T15:25:03.732385+00:00 [running]> on host 050f8c50766f
[2025-10-03T15:25:18.592+0000] {taskinstance.py:2648} INFO - Exporting env vars: AIRFLOW_CTX_DAG_OWNER='***' AIRFLOW_CTX_DAG_ID='dbt_dag' AIRFLOW_CTX_TASK_ID='dbt_deps' AIRFLOW_CTX_EXECUTION_DATE='2025-10-03T15:25:03.732385+00:00' AIRFLOW_CTX_TRY_NUMBER='1' AIRFLOW_CTX_DAG_RUN_ID='manual__2025-10-03T15:25:03.732385+00:00'
[2025-10-03T15:25:18.597+0000] {taskinstance.py:430} INFO - ::endgroup::
[2025-10-03T15:25:18.600+0000] {subprocess.py:63} INFO - Tmp dir root location: /tmp
[2025-10-03T15:25:18.602+0000] {subprocess.py:75} INFO - Running command: ['/usr/bin/bash', '-c', 'cd /opt/***/dbt && dbt deps']
[2025-10-03T15:25:18.631+0000] {subprocess.py:86} INFO - Output:
[2025-10-03T15:25:18.648+0000] {subprocess.py:93} INFO - /usr/bin/bash: line 1: dbt: command not found
[2025-10-03T15:25:18.650+0000] {subprocess.py:97} INFO - Command exited with return code 127
[2025-10-03T15:25:18.653+0000] {taskinstance.py:441} INFO - ::group::Post task execution logs
[2025-10-03T15:25:18.676+0000] {taskinstance.py:2905} ERROR - Task failed with exception
Traceback (most recent call last):
  File "/home/airflow/.local/lib/python3.12/site-packages/airflow/models/taskinstance.py", line 465, in _execute_task
    result = _execute_callable(context=context, **execute_callable_kwargs)
             ^^^^^^^^^^^^^^^^^^^^^^^^^^^^^^^^^^^^^^^^^^^^^^^^^^^^^^^^^^^^^
  File "/home/airflow/.local/lib/python3.12/site-packages/airflow/models/taskinstance.py", line 432, in _execute_callable
    return execute_callable(context=context, **execute_callable_kwargs)
           ^^^^^^^^^^^^^^^^^^^^^^^^^^^^^^^^^^^^^^^^^^^^^^^^^^^^^^^^^^^^
  File "/home/airflow/.local/lib/python3.12/site-packages/airflow/models/baseoperator.py", line 401, in wrapper
    return func(self, *args, **kwargs)
           ^^^^^^^^^^^^^^^^^^^^^^^^^^^
  File "/home/airflow/.local/lib/python3.12/site-packages/airflow/operators/bash.py", line 243, in execute
    raise AirflowException(
airflow.exceptions.AirflowException: Bash command failed. The command returned a non-zero exit code 127.
[2025-10-03T15:25:18.691+0000] {taskinstance.py:1206} INFO - Marking task as UP_FOR_RETRY. dag_id=dbt_dag, task_id=dbt_deps, run_id=manual__2025-10-03T15:25:03.732385+00:00, execution_date=20251003T152503, start_date=20251003T152518, end_date=20251003T152518
[2025-10-03T15:25:18.727+0000] {standard_task_runner.py:110} ERROR - Failed to execute job 47 for task dbt_deps (Bash command failed. The command returned a non-zero exit code 127.; 108)
[2025-10-03T15:25:18.771+0000] {local_task_job_runner.py:243} INFO - Task exited with return code 1
[2025-10-03T15:25:18.811+0000] {taskinstance.py:3503} INFO - 0 downstream tasks scheduled from follow-on schedule check
[2025-10-03T15:25:18.817+0000] {local_task_job_runner.py:222} INFO - ::endgroup::
