[2025-10-03T15:30:27.887+0000] {local_task_job_runner.py:120} INFO - ::group::Pre task execution logs
[2025-10-03T15:30:27.953+0000] {taskinstance.py:2076} INFO - Dependencies all met for dep_context=non-requeueable deps ti=<TaskInstance: dbt_dag.dbt_deps manual__2025-10-03T15:25:03.732385+00:00 [queued]>
[2025-10-03T15:30:27.970+0000] {taskinstance.py:2076} INFO - Dependencies all met for dep_context=requeueable deps ti=<TaskInstance: dbt_dag.dbt_deps manual__2025-10-03T15:25:03.732385+00:00 [queued]>
[2025-10-03T15:30:27.971+0000] {taskinstance.py:2306} INFO - Starting attempt 2 of 2
[2025-10-03T15:30:28.011+0000] {taskinstance.py:2330} INFO - Executing <Task(BashOperator): dbt_deps> on 2025-10-03 15:25:03.732385+00:00
[2025-10-03T15:30:28.040+0000] {standard_task_runner.py:90} INFO - Running: ['***', 'tasks', 'run', 'dbt_dag', 'dbt_deps', 'manual__2025-10-03T15:25:03.732385+00:00', '--job-id', '49', '--raw', '--subdir', 'DAGS_FOLDER/test_ml_dag.py', '--cfg-path', '/tmp/tmpbjsefo9_']
[2025-10-03T15:30:28.039+0000] {warnings.py:112} WARNING - /home/***/.local/lib/python3.12/site-packages/***/task/task_runner/standard_task_runner.py:62: DeprecationWarning: This process (pid=171) is multi-threaded, use of fork() may lead to deadlocks in the child.
  pid = os.fork()

[2025-10-03T15:30:28.055+0000] {standard_task_runner.py:91} INFO - Job 49: Subtask dbt_deps
[2025-10-03T15:30:28.055+0000] {standard_task_runner.py:64} INFO - Started process 173 to run task
[2025-10-03T15:30:28.373+0000] {task_command.py:426} INFO - Running <TaskInstance: dbt_dag.dbt_deps manual__2025-10-03T15:25:03.732385+00:00 [running]> on host 050f8c50766f
[2025-10-03T15:30:29.429+0000] {taskinstance.py:2648} INFO - Exporting env vars: AIRFLOW_CTX_DAG_OWNER='***' AIRFLOW_CTX_DAG_ID='dbt_dag' AIRFLOW_CTX_TASK_ID='dbt_deps' AIRFLOW_CTX_EXECUTION_DATE='2025-10-03T15:25:03.732385+00:00' AIRFLOW_CTX_TRY_NUMBER='2' AIRFLOW_CTX_DAG_RUN_ID='manual__2025-10-03T15:25:03.732385+00:00'
[2025-10-03T15:30:29.454+0000] {taskinstance.py:430} INFO - ::endgroup::
[2025-10-03T15:30:29.469+0000] {subprocess.py:63} INFO - Tmp dir root location: /tmp
[2025-10-03T15:30:29.487+0000] {subprocess.py:75} INFO - Running command: ['/usr/bin/bash', '-c', 'cd /opt/***/dbt && dbt deps']
[2025-10-03T15:30:29.585+0000] {subprocess.py:86} INFO - Output:
[2025-10-03T15:30:29.618+0000] {subprocess.py:93} INFO - /usr/bin/bash: line 1: dbt: command not found
[2025-10-03T15:30:29.620+0000] {subprocess.py:97} INFO - Command exited with return code 127
[2025-10-03T15:30:29.623+0000] {taskinstance.py:441} INFO - ::group::Post task execution logs
[2025-10-03T15:30:29.684+0000] {taskinstance.py:2905} ERROR - Task failed with exception
Traceback (most recent call last):
  File "/home/airflow/.local/lib/python3.12/site-packages/airflow/models/taskinstance.py", line 465, in _execute_task
    result = _execute_callable(context=context, **execute_callable_kwargs)
             ^^^^^^^^^^^^^^^^^^^^^^^^^^^^^^^^^^^^^^^^^^^^^^^^^^^^^^^^^^^^^
  File "/home/airflow/.local/lib/python3.12/site-packages/airflow/models/taskinstance.py", line 432, in _execute_callable
    return execute_callable(context=context, **execute_callable_kwargs)
           ^^^^^^^^^^^^^^^^^^^^^^^^^^^^^^^^^^^^^^^^^^^^^^^^^^^^^^^^^^^^
  File "/home/airflow/.local/lib/python3.12/site-packages/airflow/models/baseoperator.py", line 401, in wrapper
    return func(self, *args, **kwargs)
           ^^^^^^^^^^^^^^^^^^^^^^^^^^^
  File "/home/airflow/.local/lib/python3.12/site-packages/airflow/operators/bash.py", line 243, in execute
    raise AirflowException(
airflow.exceptions.AirflowException: Bash command failed. The command returned a non-zero exit code 127.
[2025-10-03T15:30:29.711+0000] {taskinstance.py:1206} INFO - Marking task as FAILED. dag_id=dbt_dag, task_id=dbt_deps, run_id=manual__2025-10-03T15:25:03.732385+00:00, execution_date=20251003T152503, start_date=20251003T153027, end_date=20251003T153029
[2025-10-03T15:30:29.808+0000] {standard_task_runner.py:110} ERROR - Failed to execute job 49 for task dbt_deps (Bash command failed. The command returned a non-zero exit code 127.; 173)
[2025-10-03T15:30:29.867+0000] {local_task_job_runner.py:243} INFO - Task exited with return code 1
[2025-10-03T15:30:29.960+0000] {taskinstance.py:3503} INFO - 0 downstream tasks scheduled from follow-on schedule check
[2025-10-03T15:30:29.973+0000] {local_task_job_runner.py:222} INFO - ::endgroup::
