[2025-10-03T14:46:05.600+0000] {local_task_job_runner.py:120} INFO - ::group::Pre task execution logs
[2025-10-03T14:46:05.628+0000] {taskinstance.py:2076} INFO - Dependencies all met for dep_context=non-requeueable deps ti=<TaskInstance: dbt_dag.dbt_deps scheduled__2025-10-02T00:00:00+00:00 [queued]>
[2025-10-03T14:46:05.641+0000] {taskinstance.py:2076} INFO - Dependencies all met for dep_context=requeueable deps ti=<TaskInstance: dbt_dag.dbt_deps scheduled__2025-10-02T00:00:00+00:00 [queued]>
[2025-10-03T14:46:05.666+0000] {taskinstance.py:2306} INFO - Starting attempt 2 of 2
[2025-10-03T14:46:05.887+0000] {taskinstance.py:2330} INFO - Executing <Task(BashOperator): dbt_deps> on 2025-10-02 00:00:00+00:00
[2025-10-03T14:46:05.900+0000] {warnings.py:112} WARNING - /home/***/.local/lib/python3.12/site-packages/***/task/task_runner/standard_task_runner.py:62: DeprecationWarning: This process (pid=1372) is multi-threaded, use of fork() may lead to deadlocks in the child.
  pid = os.fork()

[2025-10-03T14:46:05.904+0000] {standard_task_runner.py:64} INFO - Started process 1376 to run task
[2025-10-03T14:46:05.904+0000] {standard_task_runner.py:90} INFO - Running: ['***', 'tasks', 'run', 'dbt_dag', 'dbt_deps', 'scheduled__2025-10-02T00:00:00+00:00', '--job-id', '32', '--raw', '--subdir', 'DAGS_FOLDER/dbt_dag.py', '--cfg-path', '/tmp/tmp7rohqxrq']
[2025-10-03T14:46:05.909+0000] {standard_task_runner.py:91} INFO - Job 32: Subtask dbt_deps
[2025-10-03T14:46:06.136+0000] {task_command.py:426} INFO - Running <TaskInstance: dbt_dag.dbt_deps scheduled__2025-10-02T00:00:00+00:00 [running]> on host 68ec1039cc61
[2025-10-03T14:46:06.251+0000] {taskinstance.py:2648} INFO - Exporting env vars: AIRFLOW_CTX_DAG_OWNER='***' AIRFLOW_CTX_DAG_ID='dbt_dag' AIRFLOW_CTX_TASK_ID='dbt_deps' AIRFLOW_CTX_EXECUTION_DATE='2025-10-02T00:00:00+00:00' AIRFLOW_CTX_TRY_NUMBER='2' AIRFLOW_CTX_DAG_RUN_ID='scheduled__2025-10-02T00:00:00+00:00'
[2025-10-03T14:46:06.253+0000] {taskinstance.py:430} INFO - ::endgroup::
[2025-10-03T14:46:06.255+0000] {subprocess.py:63} INFO - Tmp dir root location: /tmp
[2025-10-03T14:46:06.257+0000] {subprocess.py:75} INFO - Running command: ['/usr/bin/bash', '-c', 'cd /opt/***/dbt && dbt deps']
[2025-10-03T14:46:06.276+0000] {subprocess.py:86} INFO - Output:
[2025-10-03T14:46:06.279+0000] {subprocess.py:93} INFO - /usr/bin/bash: line 1: cd: /opt/***/dbt: No such file or directory
[2025-10-03T14:46:06.280+0000] {subprocess.py:97} INFO - Command exited with return code 1
[2025-10-03T14:46:06.283+0000] {taskinstance.py:441} INFO - ::group::Post task execution logs
[2025-10-03T14:46:06.297+0000] {taskinstance.py:2905} ERROR - Task failed with exception
Traceback (most recent call last):
  File "/home/airflow/.local/lib/python3.12/site-packages/airflow/models/taskinstance.py", line 465, in _execute_task
    result = _execute_callable(context=context, **execute_callable_kwargs)
             ^^^^^^^^^^^^^^^^^^^^^^^^^^^^^^^^^^^^^^^^^^^^^^^^^^^^^^^^^^^^^
  File "/home/airflow/.local/lib/python3.12/site-packages/airflow/models/taskinstance.py", line 432, in _execute_callable
    return execute_callable(context=context, **execute_callable_kwargs)
           ^^^^^^^^^^^^^^^^^^^^^^^^^^^^^^^^^^^^^^^^^^^^^^^^^^^^^^^^^^^^
  File "/home/airflow/.local/lib/python3.12/site-packages/airflow/models/baseoperator.py", line 401, in wrapper
    return func(self, *args, **kwargs)
           ^^^^^^^^^^^^^^^^^^^^^^^^^^^
  File "/home/airflow/.local/lib/python3.12/site-packages/airflow/operators/bash.py", line 243, in execute
    raise AirflowException(
airflow.exceptions.AirflowException: Bash command failed. The command returned a non-zero exit code 1.
[2025-10-03T14:46:06.304+0000] {taskinstance.py:1206} INFO - Marking task as FAILED. dag_id=dbt_dag, task_id=dbt_deps, run_id=scheduled__2025-10-02T00:00:00+00:00, execution_date=20251002T000000, start_date=20251003T144605, end_date=20251003T144606
[2025-10-03T14:46:06.325+0000] {standard_task_runner.py:110} ERROR - Failed to execute job 32 for task dbt_deps (Bash command failed. The command returned a non-zero exit code 1.; 1376)
[2025-10-03T14:46:06.361+0000] {local_task_job_runner.py:243} INFO - Task exited with return code 1
[2025-10-03T14:46:06.416+0000] {taskinstance.py:3503} INFO - 0 downstream tasks scheduled from follow-on schedule check
[2025-10-03T14:46:06.427+0000] {local_task_job_runner.py:222} INFO - ::endgroup::
[2025-10-03T15:18:03.531+0000] {local_task_job_runner.py:120} INFO - ::group::Pre task execution logs
[2025-10-03T15:18:03.569+0000] {taskinstance.py:2076} INFO - Dependencies all met for dep_context=non-requeueable deps ti=<TaskInstance: dbt_dag.dbt_deps scheduled__2025-10-02T00:00:00+00:00 [queued]>
[2025-10-03T15:18:03.578+0000] {taskinstance.py:2076} INFO - Dependencies all met for dep_context=requeueable deps ti=<TaskInstance: dbt_dag.dbt_deps scheduled__2025-10-02T00:00:00+00:00 [queued]>
[2025-10-03T15:18:03.579+0000] {taskinstance.py:2306} INFO - Starting attempt 2 of 2
[2025-10-03T15:18:03.599+0000] {taskinstance.py:2330} INFO - Executing <Task(BashOperator): dbt_deps> on 2025-10-02 00:00:00+00:00
[2025-10-03T15:18:03.611+0000] {warnings.py:112} WARNING - /home/***/.local/lib/python3.12/site-packages/***/task/task_runner/standard_task_runner.py:62: DeprecationWarning: This process (pid=188) is multi-threaded, use of fork() may lead to deadlocks in the child.
  pid = os.fork()

[2025-10-03T15:18:03.613+0000] {standard_task_runner.py:64} INFO - Started process 190 to run task
[2025-10-03T15:18:03.613+0000] {standard_task_runner.py:90} INFO - Running: ['***', 'tasks', 'run', 'dbt_dag', 'dbt_deps', 'scheduled__2025-10-02T00:00:00+00:00', '--job-id', '43', '--raw', '--subdir', 'DAGS_FOLDER/dbt_dag.py', '--cfg-path', '/tmp/tmp6uy5zzoc']
[2025-10-03T15:18:03.619+0000] {standard_task_runner.py:91} INFO - Job 43: Subtask dbt_deps
[2025-10-03T15:18:03.727+0000] {task_command.py:426} INFO - Running <TaskInstance: dbt_dag.dbt_deps scheduled__2025-10-02T00:00:00+00:00 [running]> on host a73834a871b4
[2025-10-03T15:18:03.844+0000] {taskinstance.py:2648} INFO - Exporting env vars: AIRFLOW_CTX_DAG_OWNER='***' AIRFLOW_CTX_DAG_ID='dbt_dag' AIRFLOW_CTX_TASK_ID='dbt_deps' AIRFLOW_CTX_EXECUTION_DATE='2025-10-02T00:00:00+00:00' AIRFLOW_CTX_TRY_NUMBER='2' AIRFLOW_CTX_DAG_RUN_ID='scheduled__2025-10-02T00:00:00+00:00'
[2025-10-03T15:18:03.847+0000] {taskinstance.py:430} INFO - ::endgroup::
[2025-10-03T15:18:03.856+0000] {subprocess.py:63} INFO - Tmp dir root location: /tmp
[2025-10-03T15:18:03.859+0000] {subprocess.py:75} INFO - Running command: ['/usr/bin/bash', '-c', 'cd /opt/***/dbt && DBT_PROFILES_DIR=/opt/***/dbt dbt deps']
[2025-10-03T15:18:03.878+0000] {subprocess.py:86} INFO - Output:
[2025-10-03T15:18:03.915+0000] {subprocess.py:93} INFO - /usr/bin/bash: line 1: dbt: command not found
[2025-10-03T15:18:03.916+0000] {subprocess.py:97} INFO - Command exited with return code 127
[2025-10-03T15:18:03.917+0000] {taskinstance.py:441} INFO - ::group::Post task execution logs
[2025-10-03T15:18:03.935+0000] {taskinstance.py:2905} ERROR - Task failed with exception
Traceback (most recent call last):
  File "/home/airflow/.local/lib/python3.12/site-packages/airflow/models/taskinstance.py", line 465, in _execute_task
    result = _execute_callable(context=context, **execute_callable_kwargs)
             ^^^^^^^^^^^^^^^^^^^^^^^^^^^^^^^^^^^^^^^^^^^^^^^^^^^^^^^^^^^^^
  File "/home/airflow/.local/lib/python3.12/site-packages/airflow/models/taskinstance.py", line 432, in _execute_callable
    return execute_callable(context=context, **execute_callable_kwargs)
           ^^^^^^^^^^^^^^^^^^^^^^^^^^^^^^^^^^^^^^^^^^^^^^^^^^^^^^^^^^^^
  File "/home/airflow/.local/lib/python3.12/site-packages/airflow/models/baseoperator.py", line 401, in wrapper
    return func(self, *args, **kwargs)
           ^^^^^^^^^^^^^^^^^^^^^^^^^^^
  File "/home/airflow/.local/lib/python3.12/site-packages/airflow/operators/bash.py", line 243, in execute
    raise AirflowException(
airflow.exceptions.AirflowException: Bash command failed. The command returned a non-zero exit code 127.
[2025-10-03T15:18:03.948+0000] {taskinstance.py:1206} INFO - Marking task as FAILED. dag_id=dbt_dag, task_id=dbt_deps, run_id=scheduled__2025-10-02T00:00:00+00:00, execution_date=20251002T000000, start_date=20251003T151803, end_date=20251003T151803
[2025-10-03T15:18:03.981+0000] {standard_task_runner.py:110} ERROR - Failed to execute job 43 for task dbt_deps (Bash command failed. The command returned a non-zero exit code 127.; 190)
[2025-10-03T15:18:04.031+0000] {local_task_job_runner.py:243} INFO - Task exited with return code 1
[2025-10-03T15:18:04.075+0000] {taskinstance.py:3503} INFO - 0 downstream tasks scheduled from follow-on schedule check
[2025-10-03T15:18:04.084+0000] {local_task_job_runner.py:222} INFO - ::endgroup::
[2025-10-03T15:31:45.074+0000] {local_task_job_runner.py:120} INFO - ::group::Pre task execution logs
[2025-10-03T15:31:45.116+0000] {taskinstance.py:2076} INFO - Dependencies all met for dep_context=non-requeueable deps ti=<TaskInstance: dbt_dag.dbt_deps scheduled__2025-10-02T00:00:00+00:00 [queued]>
[2025-10-03T15:31:45.127+0000] {taskinstance.py:2076} INFO - Dependencies all met for dep_context=requeueable deps ti=<TaskInstance: dbt_dag.dbt_deps scheduled__2025-10-02T00:00:00+00:00 [queued]>
[2025-10-03T15:31:45.128+0000] {taskinstance.py:2306} INFO - Starting attempt 2 of 2
[2025-10-03T15:31:45.156+0000] {taskinstance.py:2330} INFO - Executing <Task(BashOperator): dbt_deps> on 2025-10-02 00:00:00+00:00
[2025-10-03T15:31:45.168+0000] {warnings.py:112} WARNING - /home/***/.local/lib/python3.12/site-packages/***/task/task_runner/standard_task_runner.py:62: DeprecationWarning: This process (pid=189) is multi-threaded, use of fork() may lead to deadlocks in the child.
  pid = os.fork()

[2025-10-03T15:31:45.181+0000] {standard_task_runner.py:64} INFO - Started process 191 to run task
[2025-10-03T15:31:45.178+0000] {standard_task_runner.py:90} INFO - Running: ['***', 'tasks', 'run', 'dbt_dag', 'dbt_deps', 'scheduled__2025-10-02T00:00:00+00:00', '--job-id', '50', '--raw', '--subdir', 'DAGS_FOLDER/test_ml_dag.py', '--cfg-path', '/tmp/tmp6pa2tek7']
[2025-10-03T15:31:45.195+0000] {standard_task_runner.py:91} INFO - Job 50: Subtask dbt_deps
[2025-10-03T15:31:45.356+0000] {task_command.py:426} INFO - Running <TaskInstance: dbt_dag.dbt_deps scheduled__2025-10-02T00:00:00+00:00 [running]> on host 050f8c50766f
[2025-10-03T15:31:45.551+0000] {taskinstance.py:2648} INFO - Exporting env vars: AIRFLOW_CTX_DAG_OWNER='***' AIRFLOW_CTX_DAG_ID='dbt_dag' AIRFLOW_CTX_TASK_ID='dbt_deps' AIRFLOW_CTX_EXECUTION_DATE='2025-10-02T00:00:00+00:00' AIRFLOW_CTX_TRY_NUMBER='2' AIRFLOW_CTX_DAG_RUN_ID='scheduled__2025-10-02T00:00:00+00:00'
[2025-10-03T15:31:45.559+0000] {taskinstance.py:430} INFO - ::endgroup::
[2025-10-03T15:31:45.562+0000] {subprocess.py:63} INFO - Tmp dir root location: /tmp
[2025-10-03T15:31:45.565+0000] {subprocess.py:75} INFO - Running command: ['/usr/bin/bash', '-c', 'cd /opt/***/dbt && dbt deps']
[2025-10-03T15:31:45.640+0000] {subprocess.py:86} INFO - Output:
[2025-10-03T15:31:45.796+0000] {subprocess.py:93} INFO - /usr/bin/bash: line 1: dbt: command not found
[2025-10-03T15:31:45.797+0000] {subprocess.py:97} INFO - Command exited with return code 127
[2025-10-03T15:31:45.799+0000] {taskinstance.py:441} INFO - ::group::Post task execution logs
[2025-10-03T15:31:45.831+0000] {taskinstance.py:2905} ERROR - Task failed with exception
Traceback (most recent call last):
  File "/home/airflow/.local/lib/python3.12/site-packages/airflow/models/taskinstance.py", line 465, in _execute_task
    result = _execute_callable(context=context, **execute_callable_kwargs)
             ^^^^^^^^^^^^^^^^^^^^^^^^^^^^^^^^^^^^^^^^^^^^^^^^^^^^^^^^^^^^^
  File "/home/airflow/.local/lib/python3.12/site-packages/airflow/models/taskinstance.py", line 432, in _execute_callable
    return execute_callable(context=context, **execute_callable_kwargs)
           ^^^^^^^^^^^^^^^^^^^^^^^^^^^^^^^^^^^^^^^^^^^^^^^^^^^^^^^^^^^^
  File "/home/airflow/.local/lib/python3.12/site-packages/airflow/models/baseoperator.py", line 401, in wrapper
    return func(self, *args, **kwargs)
           ^^^^^^^^^^^^^^^^^^^^^^^^^^^
  File "/home/airflow/.local/lib/python3.12/site-packages/airflow/operators/bash.py", line 243, in execute
    raise AirflowException(
airflow.exceptions.AirflowException: Bash command failed. The command returned a non-zero exit code 127.
[2025-10-03T15:31:45.846+0000] {taskinstance.py:1206} INFO - Marking task as FAILED. dag_id=dbt_dag, task_id=dbt_deps, run_id=scheduled__2025-10-02T00:00:00+00:00, execution_date=20251002T000000, start_date=20251003T153145, end_date=20251003T153145
[2025-10-03T15:31:46.619+0000] {standard_task_runner.py:110} ERROR - Failed to execute job 50 for task dbt_deps (Bash command failed. The command returned a non-zero exit code 127.; 191)
[2025-10-03T15:31:46.647+0000] {local_task_job_runner.py:243} INFO - Task exited with return code 1
[2025-10-03T15:31:46.727+0000] {taskinstance.py:3503} INFO - 0 downstream tasks scheduled from follow-on schedule check
[2025-10-03T15:31:46.708+0000] {local_task_job_runner.py:222} INFO - ::endgroup::
